2021-12-15 09:01:12,797 ERROR: Exception on /user/anayap [GET] [in c:\venvs\p3.9\lib\site-packages\flask\app.py:1454]
Traceback (most recent call last):
  File "c:\venvs\p3.9\lib\site-packages\flask\app.py", line 2070, in wsgi_app
    response = self.full_dispatch_request()
  File "c:\venvs\p3.9\lib\site-packages\flask\app.py", line 1515, in full_dispatch_request
    rv = self.handle_user_exception(e)
  File "c:\venvs\p3.9\lib\site-packages\flask\app.py", line 1513, in full_dispatch_request
    rv = self.dispatch_request()
  File "c:\venvs\p3.9\lib\site-packages\flask\app.py", line 1499, in dispatch_request
    return self.ensure_sync(self.view_functions[rule.endpoint])(**req.view_args)
  File "c:\venvs\p3.9\lib\site-packages\flask_login\utils.py", line 272, in decorated_view
    return func(*args, **kwargs)
  File "C:\Users\anaya.DESKTOP-7D019FO\attendance_app\app\main\routes.py", line 32, in user
    return render_template('user.html', user=user)
  File "c:\venvs\p3.9\lib\site-packages\flask\templating.py", line 147, in render_template
    return _render(
  File "c:\venvs\p3.9\lib\site-packages\flask\templating.py", line 128, in _render
    rv = template.render(context)
  File "c:\venvs\p3.9\lib\site-packages\jinja2\environment.py", line 1304, in render
    self.environment.handle_exception()
  File "c:\venvs\p3.9\lib\site-packages\jinja2\environment.py", line 925, in handle_exception
    raise rewrite_traceback_stack(source=source)
  File "C:\Users\anaya.DESKTOP-7D019FO\attendance_app\app\templates\user.html", line 1, in top-level template code
    {% extends "base.html" %}
  File "C:\Users\anaya.DESKTOP-7D019FO\attendance_app\app\templates\base.html", line 1, in top-level template code
    {% extends 'bootstrap/base.html' %}
  File "c:\venvs\p3.9\lib\site-packages\flask_bootstrap\templates\bootstrap\base.html", line 1, in top-level template code
    {% block doc -%}
  File "c:\venvs\p3.9\lib\site-packages\flask_bootstrap\templates\bootstrap\base.html", line 4, in block 'doc'
    {%- block html %}
  File "c:\venvs\p3.9\lib\site-packages\flask_bootstrap\templates\bootstrap\base.html", line 20, in block 'html'
    {% block body -%}
  File "c:\venvs\p3.9\lib\site-packages\flask_bootstrap\templates\bootstrap\base.html", line 23, in block 'body'
    {% block content -%}
  File "C:\Users\anaya.DESKTOP-7D019FO\attendance_app\app\templates\base.html", line 47, in block 'content'
    {% block app_content %}{% endblock %}
  File "C:\Users\anaya.DESKTOP-7D019FO\attendance_app\app\templates\user.html", line 13, in block 'app_content'
    <p>{{ _('%(count)d followers', count=user.followers.count()) }}, {{ _('%(count)d following', count=user.followed.count()) }}</p>
  File "c:\venvs\p3.9\lib\site-packages\jinja2\environment.py", line 474, in getattr
    return getattr(obj, attribute)
jinja2.exceptions.UndefinedError: 'app.models.User object' has no attribute 'followers'
2021-12-15 09:02:14,534 INFO: Attendance startup [in C:\Users\anaya.DESKTOP-7D019FO\attendance_app\app\__init__.py:74]
2021-12-15 09:02:14,786 ERROR: Exception on /user/anayap [GET] [in c:\venvs\p3.9\lib\site-packages\flask\app.py:1454]
Traceback (most recent call last):
  File "c:\venvs\p3.9\lib\site-packages\flask\app.py", line 2070, in wsgi_app
    response = self.full_dispatch_request()
  File "c:\venvs\p3.9\lib\site-packages\flask\app.py", line 1515, in full_dispatch_request
    rv = self.handle_user_exception(e)
  File "c:\venvs\p3.9\lib\site-packages\flask\app.py", line 1513, in full_dispatch_request
    rv = self.dispatch_request()
  File "c:\venvs\p3.9\lib\site-packages\flask\app.py", line 1499, in dispatch_request
    return self.ensure_sync(self.view_functions[rule.endpoint])(**req.view_args)
  File "c:\venvs\p3.9\lib\site-packages\flask_login\utils.py", line 272, in decorated_view
    return func(*args, **kwargs)
  File "C:\Users\anaya.DESKTOP-7D019FO\attendance_app\app\main\routes.py", line 32, in user
    return render_template('user.html', user=user)
  File "c:\venvs\p3.9\lib\site-packages\flask\templating.py", line 147, in render_template
    return _render(
  File "c:\venvs\p3.9\lib\site-packages\flask\templating.py", line 128, in _render
    rv = template.render(context)
  File "c:\venvs\p3.9\lib\site-packages\jinja2\environment.py", line 1304, in render
    self.environment.handle_exception()
  File "c:\venvs\p3.9\lib\site-packages\jinja2\environment.py", line 925, in handle_exception
    raise rewrite_traceback_stack(source=source)
  File "C:\Users\anaya.DESKTOP-7D019FO\attendance_app\app\templates\user.html", line 1, in top-level template code
    {% extends "base.html" %}
  File "C:\Users\anaya.DESKTOP-7D019FO\attendance_app\app\templates\base.html", line 1, in top-level template code
    {% extends 'bootstrap/base.html' %}
  File "c:\venvs\p3.9\lib\site-packages\flask_bootstrap\templates\bootstrap\base.html", line 1, in top-level template code
    {% block doc -%}
  File "c:\venvs\p3.9\lib\site-packages\flask_bootstrap\templates\bootstrap\base.html", line 4, in block 'doc'
    {%- block html %}
  File "c:\venvs\p3.9\lib\site-packages\flask_bootstrap\templates\bootstrap\base.html", line 20, in block 'html'
    {% block body -%}
  File "c:\venvs\p3.9\lib\site-packages\flask_bootstrap\templates\bootstrap\base.html", line 23, in block 'body'
    {% block content -%}
  File "C:\Users\anaya.DESKTOP-7D019FO\attendance_app\app\templates\base.html", line 47, in block 'content'
    {% block app_content %}{% endblock %}
  File "C:\Users\anaya.DESKTOP-7D019FO\attendance_app\app\templates\user.html", line 13, in block 'app_content'
    <p>{{ _('%(count)d followers', count=user.followers.count()) }}, {{ _('%(count)d following', count=user.followed.count()) }}</p>
  File "c:\venvs\p3.9\lib\site-packages\jinja2\environment.py", line 474, in getattr
    return getattr(obj, attribute)
jinja2.exceptions.UndefinedError: 'app.models.User object' has no attribute 'followers'
2021-12-15 09:02:43,862 INFO: Attendance startup [in C:\Users\anaya.DESKTOP-7D019FO\attendance_app\app\__init__.py:74]
2021-12-15 09:02:44,074 ERROR: Exception on /user/anayap [GET] [in c:\venvs\p3.9\lib\site-packages\flask\app.py:1454]
Traceback (most recent call last):
  File "c:\venvs\p3.9\lib\site-packages\flask\app.py", line 2070, in wsgi_app
    response = self.full_dispatch_request()
  File "c:\venvs\p3.9\lib\site-packages\flask\app.py", line 1515, in full_dispatch_request
    rv = self.handle_user_exception(e)
  File "c:\venvs\p3.9\lib\site-packages\flask\app.py", line 1513, in full_dispatch_request
    rv = self.dispatch_request()
  File "c:\venvs\p3.9\lib\site-packages\flask\app.py", line 1499, in dispatch_request
    return self.ensure_sync(self.view_functions[rule.endpoint])(**req.view_args)
  File "c:\venvs\p3.9\lib\site-packages\flask_login\utils.py", line 272, in decorated_view
    return func(*args, **kwargs)
  File "C:\Users\anaya.DESKTOP-7D019FO\attendance_app\app\main\routes.py", line 32, in user
    return render_template('user.html', user=user)
  File "c:\venvs\p3.9\lib\site-packages\flask\templating.py", line 147, in render_template
    return _render(
  File "c:\venvs\p3.9\lib\site-packages\flask\templating.py", line 128, in _render
    rv = template.render(context)
  File "c:\venvs\p3.9\lib\site-packages\jinja2\environment.py", line 1304, in render
    self.environment.handle_exception()
  File "c:\venvs\p3.9\lib\site-packages\jinja2\environment.py", line 925, in handle_exception
    raise rewrite_traceback_stack(source=source)
  File "C:\Users\anaya.DESKTOP-7D019FO\attendance_app\app\templates\user.html", line 1, in top-level template code
    {% extends "base.html" %}
  File "C:\Users\anaya.DESKTOP-7D019FO\attendance_app\app\templates\base.html", line 1, in top-level template code
    {% extends 'bootstrap/base.html' %}
  File "c:\venvs\p3.9\lib\site-packages\flask_bootstrap\templates\bootstrap\base.html", line 1, in top-level template code
    {% block doc -%}
  File "c:\venvs\p3.9\lib\site-packages\flask_bootstrap\templates\bootstrap\base.html", line 4, in block 'doc'
    {%- block html %}
  File "c:\venvs\p3.9\lib\site-packages\flask_bootstrap\templates\bootstrap\base.html", line 20, in block 'html'
    {% block body -%}
  File "c:\venvs\p3.9\lib\site-packages\flask_bootstrap\templates\bootstrap\base.html", line 23, in block 'body'
    {% block content -%}
  File "C:\Users\anaya.DESKTOP-7D019FO\attendance_app\app\templates\base.html", line 47, in block 'content'
    {% block app_content %}{% endblock %}
  File "C:\Users\anaya.DESKTOP-7D019FO\attendance_app\app\templates\user.html", line 13, in block 'app_content'
    <!-- <p>{{ _('%(count)d followers', count=user.followers.count()) }}, {{ _('%(count)d following', count=user.followed.count()) }}</p>
  File "c:\venvs\p3.9\lib\site-packages\jinja2\environment.py", line 474, in getattr
    return getattr(obj, attribute)
jinja2.exceptions.UndefinedError: 'app.models.User object' has no attribute 'followers'
2021-12-15 09:03:06,743 INFO: Attendance startup [in C:\Users\anaya.DESKTOP-7D019FO\attendance_app\app\__init__.py:74]
2021-12-15 09:04:23,192 INFO: Attendance startup [in C:\Users\anaya.DESKTOP-7D019FO\attendance_app\app\__init__.py:74]
